const x = '20'

try{
    x = 1
}
catch(e){
    console.log(`erro: ${e}`)
}
finally{
    console.log('terminamos.')
}